Workbook
Name ش146: #REF!
Name ش146: #REF!
Name ش146: #REF!
Name ش146: #REF!
Name ش146: #REF!
Name ش146: #REF!
Name ش146: #REF!
Name ش146: #REF!
Name ش146: #REF!

Sheet الاطار الموازنى  راي الجهه عام
A1: مشروع موازنة السنة المالية 2026/ 2027
D2: جهاز تنمية شبه جزيرة سيناء | P2: " القيمة بالجنيه "
A3: موازنة السنة المالية 2022/ 2023 | C3: موازنة السنة المالية 2023/ 2024 | E3: موازنة السنة المالية 2024/ 2025 | G3: الكود الاقتصادى | H3: البيان | I3: مقترح مشروع 2026/ 2027 | J3: الأطار الموازني | N3: الزيادة في راي الجهة | O3: مقترح العام المالى 2028/ 2029 | P3: التغير | R3: النسبة
A4: ربط | B4: ختامي | C4: ربط | D4: ختامي | E4: ربط | F4: ختامي | J4: مقترح العام المالى 2027/ 2028 | K4: مقترح العام المالى 2028/ 2029 | L4: المتوقع | M4: مقترح العام المالى 2029/ 2030 | P4: الزيادة | Q4: الخفض
G5: 3110000000 | H5: التكاليف و المصروفات | S5: =S437 -> 303335617
G6: 3111000000 | H6: مجموعة (1) خامات ومواد ووقود وقطع غيار | S6: =S70 -> 14899215
G7: 3111010000 | H7: بند 1 - خامات ومدخلات انتاج | S7: =S21 -> 0
G8: 3111010100 | H8: نوع(1) خامات | S8: =S12 -> 0
G9: 3111010101 | H9: فرع (1) خامات رئيسية | L9: =K9*2 -> 0 | N9: =M9-I9 -> 0 | O9: =M9 -> 0 | P9: =IF(O9>I9,O9-I9," ") | Q9: =IF(I9>O9,I9-O9," ") | R9: =IF(O9=0,,O9/I9) -> 0 | S9: =SUM(A9+B9+C9+D9+E9+F9+I9+J9+K9+L9+M9+O9) -> 0
G10: 3111010102 | H10: فرع (2) خامات مساعدة | L10: =K10*2 -> 0 | N10: =M10-I10 -> 0 | O10: =M10 -> 0 | P10: =IF(O10>I10,O10-I10," ") | Q10: =IF(I10>O10,I10-O10," ") | R10: =IF(O10=0,,O10/I10) -> 0 | S10: =SUM(A10+B10+C10+D10+E10+F10+I10+J10+K10+L10+M10+O10) -> 0
G11: 3111010103 | H11: فرع (3) أخرى | L11: =K11*2 -> 0 | N11: =M11-I11 -> 0 | O11: =M11 -> 0 | P11: =IF(O11>I11,O11-I11," ") | Q11: =IF(I11>O11,I11-O11," ") | R11: =IF(O11=0,,O11/I11) -> 0 | S11: =SUM(A11+B11+C11+D11+E11+F11+I11+J11+K11+L11+M11+O11) -> 0
A12: =SUM(A9:A11) -> 0 | B12: =SUM(B9:B11) -> 0 | C12: =SUM(C9:C11) -> 0 | D12: =SUM(D9:D11) -> 0 | E12: =SUM(E9:E11) -> 0 | F12: =SUM(F9:F11) -> 0 | H12: جملة نوع ( 1 ) | I12: =SUM(I9:I11) -> 0 | J12: =SUM(J9:J11) -> 0 | K12: =SUM(K9:K11) -> 0 | L12: =SUM(L9:L11) -> 0 | M12: =SUM(M9:M11) -> 0 | N12: =M12-I12 -> 0 | O12: =SUM(O9:O11) -> 0 | P12: =IF(O12>I12,O12-I12," ") | Q12: =IF(I12>O12,I12-O12," ") | R12: =IF(O12=0,,O12/I12) -> 0 | S12: =SUM(A12+B12+C12+D12+E12+F12+I12+J12+K12+L12+M12+O12) -> 0
A13: =A12/A847 -> 0 | B13: =B12/B847 -> 0 | C13: =C12/C847 -> 0 | D13: =D12/D847 -> 0 | E13: =E12/E847 -> 0 | F13: =F12/F847 -> #DIV/0! | H13: نسبة الى إيرادات النشاط | I13: =I12/I847 -> 0 | J13: =J12/J847 -> 0 | K13: =K12/K847 -> 0 | L13: =L12/L847 -> 0 | M13: =M12/M847 -> #DIV/0! | O13: =O12/O847 -> #DIV/0! | S13: 1
G14: 3111010200 | H14: نوع(2) مدخلات أنتاج | N14: =M14-I14 -> 0 | P14: =IF(O14>I14,O14-I14," ") | Q14: =IF(I14>O14,I14-O14," ") | S14: =S19 -> 0
G15: 3111010201 | H15: فرع (1) ألأراضي المستخدمة في تنفيذ مشروعات التعمير والإسكان التي يتم بيعها مع الوحدات السكنية المقامة عليها | L15: =K15*2 -> 0 | N15: =M15-I15 -> 0 | O15: =M15 -> 0 | P15: =IF(O15>I15,O15-I15," ") | Q15: =IF(I15>O15,I15-O15," ") | R15: =IF(O15=0,,O15/I15) -> 0 | S15: =SUM(A15+B15+C15+D15+E15+F15+I15+J15+K15+L15+M15+O15) -> 0
G16: 3111010202 | H16: فرع (2) ألأراضي المخصصة لمشروعات الاستصلاح والاستزراع التي يتم تنفيذها بغرض البيع للغير | L16: =K16*2 -> 0 | N16: =M16-I16 -> 0 | O16: =M16 -> 0 | P16: =IF(O16>I16,O16-I16," ") | Q16: =IF(I16>O16,I16-O16," ") | R16: =IF(O16=0,,O16/I16) -> 0 | S16: =SUM(A16+B16+C16+D16+E16+F16+I16+J16+K16+L16+M16+O16) -> 0
G17: 3111010203 | H17: فرع (3) مخلفات إنتاج يتم تشغيلها مرة أخري | L17: =K17*2 -> 0 | N17: =M17-I17 -> 0 | O17: =M17 -> 0 | P17: =IF(O17>I17,O17-I17," ") | Q17: =IF(I17>O17,I17-O17," ") | R17: =IF(O17=0,,O17/I17) -> 0 | S17: =SUM(A17+B17+C17+D17+E17+F17+I17+J17+K17+L17+M17+O17) -> 0
G18: 3111010204 | H18: فرع (4) مخلفات إنتاج أخري | L18: =K18*2 -> 0 | N18: =M18-I18 -> 0 | O18: =M18 -> 0 | P18: =IF(O18>I18,O18-I18," ") | Q18: =IF(I18>O18,I18-O18," ") | R18: =IF(O18=0,,O18/I18) -> 0 | S18: =SUM(A18+B18+C18+D18+E18+F18+I18+J18+K18+L18+M18+O18) -> 0
A19: =SUM(A15:A18) -> 0 | B19: =SUM(B15:B18) -> 0 | C19: =SUM(C15:C18) -> 0 | D19: =SUM(D15:D18) -> 0 | E19: =SUM(E15:E18) -> 0 | F19: =SUM(F15:F18) -> 0 | H19: جملة نوع ( 2 ) | I19: =SUM(I15:I18) -> 0 | J19: =SUM(J15:J18) -> 0 | K19: =SUM(K15:K18) -> 0 | L19: =SUM(L15:L18) -> 0 | M19: =SUM(M15:M18) -> 0 | N19: =M19-I19 -> 0 | O19: =SUM(O15:O18) -> 0 | P19: =IF(O19>I19,O19-I19," ") | Q19: =IF(I19>O19,I19-O19," ") | R19: =IF(O19=0,,O19/I19) -> 0 | S19: =SUM(A19+B19+C19+D19+E19+F19+I19+J19+K19+L19+M19+O19) -> 0
A20: =A19/A847 -> 0 | B20: =B19/B847 -> 0 | C20: =C19/C847 -> 0 | D20: =D19/D847 -> 0 | E20: =E19/E847 -> 0 | F20: =F19/F847 -> #DIV/0! | H20: نسبة الى إيرادات النشاط | I20: =I19/I847 -> 0 | J20: =J19/J847 -> 0 | K20: =K19/K847 -> 0 | L20: =L19/L847 -> 0 | M20: =M19/M847 -> #DIV/0! | O20: =O19/O847 -> #DIV/0! | S20: 1
A21: 0 | B21: 0 | C21: 0 | D21: 0 | E21: 0 | F21: =F12+F19 -> 0 | H21: جملة بند 1 - خامات ومدخلات انتاج | I21: 0 | J21: 0 | K21: 0 | L21: =K21*2 -> 0 | M21: =M12+M19 -> 0 | N21: =M21-I21 -> 0 | O21: =O12+O19 -> 0 | P21: =IF(O21>I21,O21-I21," ") | Q21: =IF(I21>O21,I21-O21," ") | R21: =IF(O21=0,,O21/I21) -> 0 | S21: =SUM(A21+B21+C21+D21+E21+F21+I21+J21+K21+L21+M21+O21) -> 0
G22: 3111020000 | H22: بند 2 وقود وزيوت | P22: =IF(O22>I22,O22-I22," ") | Q22: =IF(I22>O22,I22-O22," ") | S22: =S40 -> 5194998
G23: 3111020101 | H23: نوع (1) فحومات | L23: =K23*2 -> 0 | N23: =M23-I23 -> 0 | O23: =M23 -> 0 | P23: =IF(O23>I23,O23-I23," ") | Q23: =IF(I23>O23,I23-O23," ") | R23: =IF(O23=0,,O23/I23) -> 0 | S23: =SUM(A23+B23+C23+D23+E23+F23+I23+J23+K23+L23+M23+O23) -> 0
G24: 3111020200 | H24: نوع (2) مواد بترولية | P24: =IF(O24>I24,O24-I24," ") | Q24: =IF(I24>O24,I24-O24," ") | S24: =S27 -> 4473758
G25: 3111020201 | H25: فرع (1) مواد بترولية للتشغيل | L25: =K25*2 -> 0 | N25: =M25-I25 -> 0 | O25: =M25 -> 0 | P25: =IF(O25>I25,O25-I25," ") | Q25: =IF(I25>O25,I25-O25," ") | R25: =IF(O25=0,,O25/I25) -> 0 | S25: =SUM(A25+B25+C25+D25+E25+F25+I25+J25+K25+L25+M25+O25) -> 0
A26: 200000 | B26: 177868 | C26: 265000 | D26: 267890 | E26: 450000 | G26: 3111020202 | H26: فرع (2) مواد بترولية لسيارات الركوب | I26: 495000 | J26: 569000 | K26: 683000 | L26: =K26*2 -> 1366000 | N26: =M26-I26 -> -495000 | O26: =M26 -> 0 | P26: =IF(O26>I26,O26-I26," ") | Q26: =IF(I26>O26,I26-O26," ") -> 495000 | R26: =IF(O26=0,,O26/I26) -> 0 | S26: =SUM(A26+B26+C26+D26+E26+F26+I26+J26+K26+L26+M26+O26) -> 4473758
A27: =SUM(A25:A26) -> 200000 | B27: =SUM(B25:B26) -> 177868 | C27: =SUM(C25:C26) -> 265000 | D27: =SUM(D25:D26) -> 267890 | E27: =SUM(E25:E26) -> 450000 | F27: =SUM(F25:F26) -> 0 | H27: جملة نوع ( 2 ) | I27: =SUM(I25:I26) -> 495000 | J27: =SUM(J25:J26) -> 569000 | K27: =SUM(K25:K26) -> 683000 | L27: =SUM(L25:L26) -> 1366000 | M27: =SUM(M25:M26) -> 0 | N27: =M27-I27 -> -495000 | O27: =SUM(O25:O26) -> 0 | P27: =IF(O27>I27,O27-I27," ") | Q27: =IF(I27>O27,I27-O27," ") -> 495000 | R27: =IF(O27=0,,O27/I27) -> 0 | S27: =SUM(A27+B27+C27+D27+E27+F27+I27+J27+K27+L27+M27+O27) -> 4473758
A28: =A27/A847 -> 0.0090909091 | B28: =B27/B847 -> 0.0071065233 | C28: =C27/C847 -> 0.014082262 | D28: =D27/D847 -> 0.0083492858 | E28: =E27/E847 -> 0.014601856 | F28: =F27/F847 -> #DIV/0! | H28: نسبة الى إيرادات النشاط | I28: =I27/I847 -> 0.012556122 | J28: =J27/J847 -> 0.012499176 | K28: =K27/K847 -> 0.01250389 | L28: =L27/L847 -> 0.012506523 | M28: =M27/M847 -> #DIV/0! | O28: =O27/O847 -> #DIV/0! | S28: 1
G29: 3111020300 | H29: نوع (3) مواد تزييت و تشحيم | P29: =IF(O29>I29,O29-I29," ") | Q29: =IF(I29>O29,I29-O29," ") | S29: =S32 -> 649315
G30: 3111020301 | H30: فرع (1) مواد تزييت و شحومات للتشغيل | L30: =K30*2 -> 0 | N30: =M30-I30 -> 0 | O30: =M30 -> 0 | P30: =IF(O30>I30,O30-I30," ") | Q30: =IF(I30>O30,I30-O30," ") | R30: =IF(O30=0,,O30/I30) -> 0 | S30: =SUM(A30+B30+C30+D30+E30+F30+I30+J30+K30+L30+M30+O30) -> 0
A31: 15000 | B31: 17422 | C31: 23000 | D31: 29893 | E31: 45000 | G31: 3111020302 | H31: فرع (2) مواد تزييت وشحومات لسيارات الركوب | I31: 82000 | J31: 95000 | K31: 114000 | L31: =K31*2 -> 228000 | N31: =M31-I31 -> -82000 | O31: =M31 -> 0 | P31: =IF(O31>I31,O31-I31," ") | Q31: =IF(I31>O31,I31-O31," ") -> 82000 | R31: =IF(O31=0,,O31/I31) -> 0 | S31: =SUM(A31+B31+C31+D31+E31+F31+I31+J31+K31+L31+M31+O31) -> 649315
A32: =SUM(A30:A31) -> 15000 | B32: =SUM(B30:B31) -> 17422 | C32: =SUM(C30:C31) -> 23000 | D32: =SUM(D30:D31) -> 29893 | E32: =SUM(E30:E31) -> 45000 | F32: =SUM(F30:F31) -> 0 | H32: جملة نوع ( 3 ) | I32: =SUM(I30:I31) -> 82000 | J32: =SUM(J30:J31) -> 95000 | K32: =SUM(K30:K31) -> 114000 | L32: =SUM(L30:L31) -> 228000 | M32: =SUM(M30:M31) -> 0 | N32: =M32-I32 -> -82000 | O32: =SUM(O30:O31) -> 0 | P32: =IF(O32>I32,O32-I32," ") | Q32: =IF(I32>O32,I32-O32," ") -> 82000 | R32: =IF(O32=0,,O32/I32) -> 0 | S32: =SUM(A32+B32+C32+D32+E32+F32+I32+J32+K32+L32+M32+O32) -> 649315
A33: =A32/A847 -> 0.00068181818 | B33: =B32/B847 -> 0.00069607714 | C33: =C32/C847 -> 0.001222234 | D33: =D32/D847 -> 0.00093167047 | E33: =E32/E847 -> 0.0014601856 | F33: =F32/F847 -> #DIV/0! | H33: نسبة الى إيرادات النشاط | I33: =I32/I847 -> 0.0020800041 | J33: =J32/J847 -> 0.0020868572 | K33: =K32/K847 -> 0.0020870329 | L33: =L32/L847 -> 0.0020874724 | M33: =M32/M847 -> #DIV/0! | O33: =O32/O847 -> #DIV/0! | S33: 1
G34: 3111020400 | H34: نوع (4) غاز | P34: =IF(O34>I34,O34-I34," ") | Q34: =IF(I34>O34,I34-O34," ") | S34: =S36 -> 0
C35: 14000 | D35: 1925 | E35: 14000 | G35: 3111020401 | H35: فرع (1) غاز للتشغيل | I35: 7000 | J35: 8000 | K35: 9000 | L35: =K35*2 -> 18000 | N35: =M35-I35 -> -7000 | O35: =M35 -> 0 | P35: =IF(O35>I35,O35-I35," ") | Q35: =IF(I35>O35,I35-O35," ") -> 7000 | R35: =IF(O35=0,,O35/I35) -> 0 | S35: =SUM(A35+B35+C35+D35+E35+F35+I35+J35+K35+L35+M35+O35) -> 71925
G36: 3111020402 | H36: فرع (2) غاز لسيارات الركوب | L36: =K36*2 -> 0 | N36: =M36-I36 -> 0 | O36: =M36 -> 0 | P36: =IF(O36>I36,O36-I36," ") | Q36: =IF(I36>O36,I36-O36," ") | R36: =IF(O36=0,,O36/I36) -> 0 | S36: =SUM(A36+B36+C36+D36+E36+F36+I36+J36+K36+L36+M36+O36) -> 0
A37: =SUM(A35:A36) -> 0 | B37: =SUM(B35:B36) -> 0 | C37: =SUM(C35:C36) -> 14000 | D37: =SUM(D35:D36) -> 1925 | E37: =SUM(E35:E36) -> 14000 | F37: =SUM(F35:F36) -> 0 | H37: جملة نوع ( 4 ) | I37: =SUM(I35:I36) -> 7000 | J37: =SUM(J35:J36) -> 8000 | K37: =SUM(K35:K36) -> 9000 | L37: =SUM(L35:L36) -> 18000 | M37: =SUM(M35:M36) -> 0 | N37: =M37-I37 -> -7000 | O37: =SUM(O35:O36) -> 0 | P37: =IF(O37>I37,O37-I37," ") | Q37: =IF(I37>O37,I37-O37," ") -> 7000 | R37: =IF(O37=0,,O37/I37) -> 0 | S37: =SUM(A37+B37+C37+D37+E37+F37+I37+J37+K37+L37+M37+O37) -> 71925
A38: =A37/A847 -> 0 | B38: =B37/B847 -> 0 | C38: =C37/C847 -> 0.00074396854 | D38: =D37/D847 -> 5.9996175e-05 | E38: =E37/E847 -> 0.00045427997 | F38: =F37/F847 -> #DIV/0! | H38: نسبة الى إيرادات النشاط | I38: =I37/I847 -> 0.00017756132 | J38: =J37/J847 -> 0.00017573534 | K38: =K37/K847 -> 0.00016476576 | L38: =L37/L847 -> 0.00016480045 | M38: =M37/M847 -> #DIV/0! | O38: =O37/O847 -> #DIV/0! | S38: 1
G39: 3111020501 | H39: نوع(5) أخرى | L39: =K39*2 -> 0 | N39: =M39-I39 -> 0 | O39: =M39 -> 0 | P39: =IF(O39>I39,O39-I39," ") | Q39: =IF(I39>O39,I39-O39," ") | R39: =IF(O39=0,,O39/I39) -> 0 | S39: =SUM(A39+B39+C39+D39+E39+F39+I39+J39+K39+L39+M39+O39) -> 0
A40: =A23+A27+A32+A37+A39 -> 215000 | B40: =B23+B27+B32+B37+B39 -> 195290 | C40: =C23+C27+C32+C37+C39 -> 302000 | D40: =D23+D27+D32+D37+D39 -> 299708 | E40: =E23+E27+E32+E37+E39 -> 509000 | F40: =F23+F27+F32+F37+F39 -> 0 | H40: جملة بند (2) وقود وزيوت | I40: =I23+I27+I32+I37+I39 -> 584000 | J40: =J23+J27+J32+J37+J39 -> 672000 | K40: =K23+K27+K32+K37+K39 -> 806000 | L40: =L23+L27+L32+L37+L39 -> 1612000 | M40: =M23+M27+M32+M37+M39 -> 0 | N40: =M40-I40 -> -584000 | O40: =O23+O27+O32+O37+O39 -> 0 | P40: =IF(O40>I40,O40-I40," ") | Q40: =IF(I40>O40,I40-O40," ") -> 584000 | R40: =IF(O40=0,,O40/I40) -> 0 | S40: =SUM(A40+B40+C40+D40+E40+F40+I40+J40+K40+L40+M40+O40) -> 5194998
...

Sheet موازنة 2026-2027
A1: ='الاطار الموازنى راي الجهه عام'!A1:R1 -> مشروع موازنة السنة المالية 2026/ 2027
D2: ='الاطار الموازنى راي الجهه عام'!D2:O2 -> جهاز تنمية شبه جزيرة سيناء | P2: " القيمة بالجنيه "
A3: ='الاطار الموازنى راي الجهه عام'!A3:B3 -> موازنة السنة المالية 2022/ 2023 | C3: ='الاطار الموازنى راي الجهه عام'!C3:D3 -> موازنة السنة المالية 2023/ 2024 | E3: ='الاطار الموازنى راي الجهه عام'!E3:F3 -> موازنة السنة المالية 2024/ 2025 | G3: الكود الاقتصادى | H3: البيان | I3: موازنة السنة المالية 2025/ 2026 | M3: مقترح الجهه | N3: الزيادة في راي الجهة | O3: موازنة العام المالى 2026/ 2027 | P3: التغير | R3: النسبة
A4: ربط | B4: ختامي | C4: ربط | D4: ختامي | E4: ربط | F4: ختامي | I4: ربط 2025/ 2026 | J4: ربط معدل ديسمبر2025 | K4: فعلى ديسمبر2025 | L4: المتوقع | P4: الزيادة | Q4: الخفض
G5: 3110000000 | H5: التكاليف و المصروفات | S5: =S437 -> 252751683
G6: 3111000000 | H6: مجموعة (1) خامات ومواد ووقود وقطع غيار | S6: =S70 -> 11803801
G7: 3111010000 | H7: بند 1 - خامات ومدخلات انتاج | S7: =S21 -> 0
G8: 3111010100 | H8: نوع(1) خامات | S8: =S12 -> 0
A9: ='الاطار الموازنى راي الجهه عام'!A9 -> 0 | B9: ='الاطار الموازنى راي الجهه عام'!B9 -> 0 | C9: ='الاطار الموازنى راي الجهه عام'!C9 -> 0 | D9: ='الاطار الموازنى راي الجهه عام'!D9 -> 0 | E9: ='الاطار الموازنى راي الجهه عام'!E9 -> 0 | F9: ='الاطار الموازنى راي الجهه عام'!F9 -> 0 | G9: 3111010101 | H9: فرع (1) خامات رئيسية | L9: =K9*2 -> 0 | M9: ='الاطار الموازنى راي الجهه عام'!I9 -> 0 | N9: =M9-I9 -> 0 | P9: =IF(O9>I9,O9-I9," ") | Q9: =IF(I9>O9,I9-O9," ") | R9: =IF(O9=0,,O9/I9) -> 0 | S9: =SUM(A9+B9+C9+D9+E9+F9+I9+J9+K9+L9+M9+O9) -> 0
A10: ='الاطار الموازنى راي الجهه عام'!A10 -> 0 | B10: ='الاطار الموازنى راي الجهه عام'!B10 -> 0 | C10: ='الاطار الموازنى راي الجهه عام'!C10 -> 0 | D10: ='الاطار الموازنى راي الجهه عام'!D10 -> 0 | E10: ='الاطار الموازنى راي الجهه عام'!E10 -> 0 | F10: ='الاطار الموازنى راي الجهه عام'!F10 -> 0 | G10: 3111010102 | H10: فرع (2) خامات مساعدة | L10: =K10*2 -> 0 | M10: ='الاطار الموازنى راي الجهه عام'!I10 -> 0 | N10: =M10-I10 -> 0 | P10: =IF(O10>I10,O10-I10," ") | Q10: =IF(I10>O10,I10-O10," ") | R10: =IF(O10=0,,O10/I10) -> 0 | S10: =SUM(A10+B10+C10+D10+E10+F10+I10+J10+K10+L10+M10+O10) -> 0
A11: ='الاطار الموازنى راي الجهه عام'!A11 -> 0 | B11: ='الاطار الموازنى راي الجهه عام'!B11 -> 0 | C11: ='الاطار الموازنى راي الجهه عام'!C11 -> 0 | D11: ='الاطار الموازنى راي الجهه عام'!D11 -> 0 | E11: ='الاطار الموازنى راي الجهه عام'!E11 -> 0 | F11: ='الاطار الموازنى راي الجهه عام'!F11 -> 0 | G11: 3111010103 | H11: فرع (3) أخرى | L11: =K11*2 -> 0 | M11: ='الاطار الموازنى راي الجهه عام'!I11 -> 0 | N11: =M11-I11 -> 0 | P11: =IF(O11>I11,O11-I11," ") | Q11: =IF(I11>O11,I11-O11," ") | R11: =IF(O11=0,,O11/I11) -> 0 | S11: =SUM(A11+B11+C11+D11+E11+F11+I11+J11+K11+L11+M11+O11) -> 0
A12: =SUM(A9:A11) -> 0 | B12: =SUM(B9:B11) -> 0 | C12: =SUM(C9:C11) -> 0 | D12: =SUM(D9:D11) -> 0 | E12: =SUM(E9:E11) -> 0 | F12: ='الاطار الموازنى راي الجهه عام'!F12 -> 0 | H12: جملة نوع ( 1 ) | I12: =SUM(I9:I11) -> 0 | J12: =SUM(J9:J11) -> 0 | K12: =SUM(K9:K11) -> 0 | L12: =SUM(L9:L11) -> 0 | M12: ='الاطار الموازنى راي الجهه عام'!I12 -> 0 | N12: =M12-I12 -> 0 | O12: =SUM(O9:O11) -> 0 | P12: =IF(O12>I12,O12-I12," ") | Q12: =IF(I12>O12,I12-O12," ") | R12: =IF(O12=0,,O12/I12) -> 0 | S12: =SUM(A12+B12+C12+D12+E12+F12+I12+J12+K12+L12+M12+O12) -> 0
A13: =A12/A847 -> 0 | B13: =B12/B847 -> 0 | C13: =C12/C847 -> 0 | D13: =D12/D847 -> 0 | E13: =E12/E847 -> 0 | F13: ='الاطار الموازنى راي الجهه عام'!F13 -> #DIV/0! | H13: نسبة الى إيرادات النشاط | I13: =I12/I847 -> 0 | J13: =J12/J847 -> 0 | K13: =K12/K847 -> #DIV/0! | L13: =L12/L847 -> #DIV/0! | M13: ='الاطار الموازنى راي الجهه عام'!I13 -> 0 | O13: =O12/O847 -> 0 | S13: 1
G14: 3111010200 | H14: نوع(2) مدخلات أنتاج | P14: =IF(O14>I14,O14-I14," ") | Q14: =IF(I14>O14,I14-O14," ") | S14: =S19 -> 0
A15: ='الاطار الموازنى راي الجهه عام'!A15 -> 0 | B15: ='الاطار الموازنى راي الجهه عام'!B15 -> 0 | C15: ='الاطار الموازنى راي الجهه عام'!C15 -> 0 | D15: ='الاطار الموازنى راي الجهه عام'!D15 -> 0 | E15: ='الاطار الموازنى راي الجهه عام'!E15 -> 0 | F15: ='الاطار الموازنى راي الجهه عام'!F15 -> 0 | G15: 3111010201 | H15: فرع (1) ألأراضي المستخدمة في تنفيذ مشروعات التعمير والإسكان التي يتم بيعها مع الوحدات السكنية المقامة عليها | L15: =K15*2 -> 0 | M15: ='الاطار الموازنى راي الجهه عام'!I15 -> 0 | N15: =M15-I15 -> 0 | P15: =IF(O15>I15,O15-I15," ") | Q15: =IF(I15>O15,I15-O15," ") | R15: =IF(O15=0,,O15/I15) -> 0 | S15: =SUM(A15+B15+C15+D15+E15+F15+I15+J15+K15+L15+M15+O15) -> 0
A16: ='الاطار الموازنى راي الجهه عام'!A16 -> 0 | B16: ='الاطار الموازنى راي الجهه عام'!B16 -> 0 | C16: ='الاطار الموازنى راي الجهه عام'!C16 -> 0 | D16: ='الاطار الموازنى راي الجهه عام'!D16 -> 0 | E16: ='الاطار الموازنى راي الجهه عام'!E16 -> 0 | F16: ='الاطار الموازنى راي الجهه عام'!F16 -> 0 | G16: 3111010202 | H16: فرع (2) ألأراضي المخصصة لمشروعات الاستصلاح والاستزراع التي يتم تنفيذها بغرض البيع للغير | L16: =K16*2 -> 0 | M16: ='الاطار الموازنى راي الجهه عام'!I16 -> 0 | N16: =M16-I16 -> 0 | P16: =IF(O16>I16,O16-I16," ") | Q16: =IF(I16>O16,I16-O16," ") | R16: =IF(O16=0,,O16/I16) -> 0 | S16: =SUM(A16+B16+C16+D16+E16+F16+I16+J16+K16+L16+M16+O16) -> 0
A17: ='الاطار الموازنى راي الجهه عام'!A17 -> 0 | B17: ='الاطار الموازنى راي الجهه عام'!B17 -> 0 | C17: ='الاطار الموازنى راي الجهه عام'!C17 -> 0 | D17: ='الاطار الموازنى راي الجهه عام'!D17 -> 0 | E17: ='الاطار الموازنى راي الجهه عام'!E17 -> 0 | F17: ='الاطار الموازنى راي الجهه عام'!F17 -> 0 | G17: 3111010203 | H17: فرع (3) مخلفات إنتاج يتم تشغيلها مرة أخري | L17: =K17*2 -> 0 | M17: ='الاطار الموازنى راي الجهه عام'!I17 -> 0 | N17: =M17-I17 -> 0 | P17: =IF(O17>I17,O17-I17," ") | Q17: =IF(I17>O17,I17-O17," ") | R17: =IF(O17=0,,O17/I17) -> 0 | S17: =SUM(A17+B17+C17+D17+E17+F17+I17+J17+K17+L17+M17+O17) -> 0
A18: ='الاطار الموازنى راي الجهه عام'!A18 -> 0 | B18: ='الاطار الموازنى راي الجهه عام'!B18 -> 0 | C18: ='الاطار الموازنى راي الجهه عام'!C18 -> 0 | D18: ='الاطار الموازنى راي الجهه عام'!D18 -> 0 | E18: ='الاطار الموازنى راي الجهه عام'!E18 -> 0 | F18: ='الاطار الموازنى راي الجهه عام'!F18 -> 0 | G18: 3111010204 | H18: فرع (4) مخلفات إنتاج أخري | L18: =K18*2 -> 0 | M18: ='الاطار الموازنى راي الجهه عام'!I18 -> 0 | N18: =M18-I18 -> 0 | P18: =IF(O18>I18,O18-I18," ") | Q18: =IF(I18>O18,I18-O18," ") | R18: =IF(O18=0,,O18/I18) -> 0 | S18: =SUM(A18+B18+C18+D18+E18+F18+I18+J18+K18+L18+M18+O18) -> 0
A19: =SUM(A15:A18) -> 0 | B19: =SUM(B15:B18) -> 0 | C19: =SUM(C15:C18) -> 0 | D19: =SUM(D15:D18) -> 0 | E19: =SUM(E15:E18) -> 0 | F19: ='الاطار الموازنى راي الجهه عام'!F19 -> 0 | H19: جملة نوع ( 2 ) | I19: =SUM(I15:I18) -> 0 | J19: =SUM(J15:J18) -> 0 | K19: =SUM(K15:K18) -> 0 | L19: =SUM(L15:L18) -> 0 | M19: ='الاطار الموازنى راي الجهه عام'!I19 -> 0 | N19: =M19-I19 -> 0 | O19: =SUM(O15:O18) -> 0 | P19: =IF(O19>I19,O19-I19," ") | Q19: =IF(I19>O19,I19-O19," ") | R19: =IF(O19=0,,O19/I19) -> 0 | S19: =SUM(A19+B19+C19+D19+E19+F19+I19+J19+K19+L19+M19+O19) -> 0
A20: =A19/A847 -> 0 | B20: =B19/B847 -> 0 | C20: =C19/C847 -> 0 | D20: =D19/D847 -> 0 | E20: =E19/E847 -> 0 | F20: ='الاطار الموازنى راي الجهه عام'!F20 -> #DIV/0! | H20: نسبة الى إيرادات النشاط | I20: =I19/I847 -> 0 | J20: =J19/J847 -> 0 | K20: =K19/K847 -> #DIV/0! | L20: =L19/L847 -> #DIV/0! | M20: ='الاطار الموازنى راي الجهه عام'!I20 -> 0 | O20: =O19/O847 -> 0 | S20: 1
A21: =A12+A19 -> 0 | B21: =B12+B19 -> 0 | C21: =C12+C19 -> 0 | D21: =D12+D19 -> 0 | E21: =E12+E19 -> 0 | F21: ='الاطار الموازنى راي الجهه عام'!F21 -> 0 | H21: جملة بند 1 - خامات ومدخلات انتاج | I21: =I12+I19 -> 0 | J21: =J12+J19 -> 0 | K21: =K12+K19 -> 0 | L21: =K21*2 -> 0 | M21: ='الاطار الموازنى راي الجهه عام'!I21 -> 0 | N21: =M21-I21 -> 0 | O21: =O12+O19 -> 0 | P21: =IF(O21>I21,O21-I21," ") | Q21: =IF(I21>O21,I21-O21," ") | R21: =IF(O21=0,,O21/I21) -> 0 | S21: =SUM(A21+B21+C21+D21+E21+F21+I21+J21+K21+L21+M21+O21) -> 0
G22: 3111020000 | H22: بند 2 وقود وزيوت | P22: =IF(O22>I22,O22-I22," ") | Q22: =IF(I22>O22,I22-O22," ") | S22: =S40 -> 3812998
A23: ='الاطار الموازنى راي الجهه عام'!A23 -> 0 | B23: ='الاطار الموازنى راي الجهه عام'!B23 -> 0 | C23: ='الاطار الموازنى راي الجهه عام'!C23 -> 0 | D23: ='الاطار الموازنى راي الجهه عام'!D23 -> 0 | E23: ='الاطار الموازنى راي الجهه عام'!E23 -> 0 | F23: ='الاطار الموازنى راي الجهه عام'!F23 -> 0 | G23: 3111020101 | H23: نوع (1) فحومات | L23: =K23*2 -> 0 | M23: ='الاطار الموازنى راي الجهه عام'!I23 -> 0 | N23: =M23-I23 -> 0 | P23: =IF(O23>I23,O23-I23," ") | Q23: =IF(I23>O23,I23-O23," ") | R23: =IF(O23=0,,O23/I23) -> 0 | S23: =SUM(A23+B23+C23+D23+E23+F23+I23+J23+K23+L23+M23+O23) -> 0
G24: 3111020200 | H24: نوع (2) مواد بترولية | P24: =IF(O24>I24,O24-I24," ") | Q24: =IF(I24>O24,I24-O24," ") | S24: =S27 -> 3340758
A25: ='الاطار الموازنى راي الجهه عام'!A25 -> 0 | B25: ='الاطار الموازنى راي الجهه عام'!B25 -> 0 | C25: ='الاطار الموازنى راي الجهه عام'!C25 -> 0 | D25: ='الاطار الموازنى راي الجهه عام'!D25 -> 0 | E25: ='الاطار الموازنى راي الجهه عام'!E25 -> 0 | F25: ='الاطار الموازنى راي الجهه عام'!F25 -> 0 | G25: 3111020201 | H25: فرع (1) مواد بترولية للتشغيل | L25: =K25*2 -> 0 | M25: ='الاطار الموازنى راي الجهه عام'!I25 -> 0 | N25: =M25-I25 -> 0 | P25: =IF(O25>I25,O25-I25," ") | Q25: =IF(I25>O25,I25-O25," ") | R25: =IF(O25=0,,O25/I25) -> 0 | S25: =SUM(A25+B25+C25+D25+E25+F25+I25+J25+K25+L25+M25+O25) -> 0
A26: ='الاطار الموازنى راي الجهه عام'!A26 -> 200000 | B26: ='الاطار الموازنى راي الجهه عام'!B26 -> 177868 | C26: ='الاطار الموازنى راي الجهه عام'!C26 -> 265000 | D26: ='الاطار الموازنى راي الجهه عام'!D26 -> 267890 | E26: ='الاطار الموازنى راي الجهه عام'!E26 -> 450000 | F26: ='الاطار الموازنى راي الجهه عام'!F26 -> 0 | G26: 3111020202 | H26: فرع (2) مواد بترولية لسيارات الركوب | I26: 495000 | J26: 495000 | L26: =K26*2 -> 0 | M26: ='الاطار الموازنى راي الجهه عام'!I26 -> 495000 | N26: =M26-I26 -> 0 | O26: 495000 | P26: =IF(O26>I26,O26-I26," ") | Q26: =IF(I26>O26,I26-O26," ") | R26: =IF(O26=0,,O26/I26) -> 1 | S26: =SUM(A26+B26+C26+D26+E26+F26+I26+J26+K26+L26+M26+O26) -> 3340758
A27: =SUM(A25:A26) -> 200000 | B27: =SUM(B25:B26) -> 177868 | C27: =SUM(C25:C26) -> 265000 | D27: =SUM(D25:D26) -> 267890 | E27: =SUM(E25:E26) -> 450000 | F27: ='الاطار الموازنى راي الجهه عام'!F27 -> 0 | H27: جملة نوع ( 2 ) | I27: =SUM(I25:I26) -> 495000 | J27: =SUM(J25:J26) -> 495000 | K27: =SUM(K25:K26) -> 0 | L27: =SUM(L25:L26) -> 0 | M27: ='الاطار الموازنى راي الجهه عام'!I27 -> 495000 | N27: =M27-I27 -> 0 | O27: =SUM(O25:O26) -> 495000 | P27: =IF(O27>I27,O27-I27," ") | Q27: =IF(I27>O27,I27-O27," ") | R27: =IF(O27=0,,O27/I27) -> 1 | S27: =SUM(A27+B27+C27+D27+E27+F27+I27+J27+K27+L27+M27+O27) -> 3340758
A28: =A27/A847 -> 0.0090909091 | B28: =B27/B847 -> 0.0071065233 | C28: =C27/C847 -> 0.014082262 | D28: =D27/D847 -> 0.0083492858 | E28: =E27/E847 -> 0.014601856 | F28: ='الاطار الموازنى راي الجهه عام'!F28 -> #DIV/0! | H28: نسبة الى إيرادات النشاط | I28: =I27/I847 -> 0.012556122 | J28: =J27/J847 -> 0.012556122 | K28: =K27/K847 -> #DIV/0! | L28: =L27/L847 -> #DIV/0! | M28: ='الاطار الموازنى راي الجهه عام'!I28 -> 0.012556122 | O28: =O27/O847 -> 0.012556122 | S28: 1
G29: 3111020300 | H29: نوع (3) مواد تزييت و تشحيم | P29: =IF(O29>I29,O29-I29," ") | Q29: =IF(I29>O29,I29-O29," ") | S29: =S32 -> 414315
A30: ='الاطار الموازنى راي الجهه عام'!A30 -> 0 | B30: ='الاطار الموازنى راي الجهه عام'!B30 -> 0 | C30: ='الاطار الموازنى راي الجهه عام'!C30 -> 0 | D30: ='الاطار الموازنى راي الجهه عام'!D30 -> 0 | E30: ='الاطار الموازنى راي الجهه عام'!E30 -> 0 | F30: ='الاطار الموازنى راي الجهه عام'!F30 -> 0 | G30: 3111020301 | H30: فرع (1) مواد تزييت و شحومات للتشغيل | L30: =K30*2 -> 0 | M30: ='الاطار الموازنى راي الجهه عام'!I30 -> 0 | N30: =M30-I30 -> 0 | P30: =IF(O30>I30,O30-I30," ") | Q30: =IF(I30>O30,I30-O30," ") | R30: =IF(O30=0,,O30/I30) -> 0 | S30: =SUM(A30+B30+C30+D30+E30+F30+I30+J30+K30+L30+M30+O30) -> 0
A31: ='الاطار الموازنى راي الجهه عام'!A31 -> 15000 | B31: ='الاطار الموازنى راي الجهه عام'!B31 -> 17422 | C31: ='الاطار الموازنى راي الجهه عام'!C31 -> 23000 | D31: ='الاطار الموازنى راي الجهه عام'!D31 -> 29893 | E31: ='الاطار الموازنى راي الجهه عام'!E31 -> 45000 | F31: ='الاطار الموازنى راي الجهه عام'!F31 -> 0 | G31: 3111020302 | H31: فرع (2) مواد تزييت وشحومات لسيارات الركوب | I31: 60000 | J31: 60000 | L31: =K31*2 -> 0 | M31: ='الاطار الموازنى راي الجهه عام'!I31 -> 82000 | N31: =M31-I31 -> 22000 | O31: 82000 | P31: =IF(O31>I31,O31-I31," ") -> 22000 | Q31: =IF(I31>O31,I31-O31," ") | R31: =IF(O31=0,,O31/I31) -> 1.3666667 | S31: =SUM(A31+B31+C31+D31+E31+F31+I31+J31+K31+L31+M31+O31) -> 414315
A32: =SUM(A30:A31) -> 15000 | B32: =SUM(B30:B31) -> 17422 | C32: =SUM(C30:C31) -> 23000 | D32: =SUM(D30:D31) -> 29893 | E32: =SUM(E30:E31) -> 45000 | F32: ='الاطار الموازنى راي الجهه عام'!F32 -> 0 | H32: جملة نوع ( 3 ) | I32: =SUM(I30:I31) -> 60000 | J32: =SUM(J30:J31) -> 60000 | K32: =SUM(K30:K31) -> 0 | L32: =SUM(L30:L31) -> 0 | M32: ='الاطار الموازنى راي الجهه عام'!I32 -> 82000 | N32: =M32-I32 -> 22000 | O32: =SUM(O30:O31) -> 82000 | P32: =IF(O32>I32,O32-I32," ") -> 22000 | Q32: =IF(I32>O32,I32-O32," ") | R32: =IF(O32=0,,O32/I32) -> 1.3666667 | S32: =SUM(A32+B32+C32+D32+E32+F32+I32+J32+K32+L32+M32+O32) -> 414315
A33: =A32/A847 -> 0.00068181818 | B33: =B32/B847 -> 0.00069607714 | C33: =C32/C847 -> 0.001222234 | D33: =D32/D847 -> 0.00093167047 | E33: =E32/E847 -> 0.0014601856 | F33: ='الاطار الموازنى راي الجهه عام'!F33 -> #DIV/0! | H33: نسبة الى إيرادات النشاط | I33: =I32/I847 -> 0.0015219542 | J33: =J32/J847 -> 0.0015219542 | K33: =K32/K847 -> #DIV/0! | L33: =L32/L847 -> #DIV/0! | M33: ='الاطار الموازنى راي الجهه عام'!I33 -> 0.0020800041 | O33: =O32/O847 -> 0.0020800041 | S33: 1
G34: 3111020400 | H34: نوع (4) غاز | P34: =IF(O34>I34,O34-I34," ") | Q34: =IF(I34>O34,I34-O34," ") | S34: =S36 -> 0
A35: ='الاطار الموازنى راي الجهه عام'!A35 -> 0 | B35: ='الاطار الموازنى راي الجهه عام'!B35 -> 0 | C35: ='الاطار الموازنى راي الجهه عام'!C35 -> 14000 | D35: ='الاطار الموازنى راي الجهه عام'!D35 -> 1925 | E35: ='الاطار الموازنى راي الجهه عام'!E35 -> 14000 | F35: ='الاطار الموازنى راي الجهه عام'!F35 -> 0 | G35: 3111020401 | H35: فرع (1) غاز للتشغيل | I35: 7000 | J35: 7000 | L35: =K35*2 -> 0 | M35: ='الاطار الموازنى راي الجهه عام'!I35 -> 7000 | N35: =M35-I35 -> 0 | O35: 7000 | P35: =IF(O35>I35,O35-I35," ") | Q35: =IF(I35>O35,I35-O35," ") | R35: =IF(O35=0,,O35/I35) -> 1 | S35: =SUM(A35+B35+C35+D35+E35+F35+I35+J35+K35+L35+M35+O35) -> 57925
A36: ='الاطار الموازنى راي الجهه عام'!A36 -> 0 | B36: ='الاطار الموازنى راي الجهه عام'!B36 -> 0 | C36: ='الاطار الموازنى راي الجهه عام'!C36 -> 0 | D36: ='الاطار الموازنى راي الجهه عام'!D36 -> 0 | E36: ='الاطار الموازنى راي الجهه عام'!E36 -> 0 | F36: ='الاطار الموازنى راي الجهه عام'!F36 -> 0 | G36: 3111020402 | H36: فرع (2) غاز لسيارات الركوب | L36: =K36*2 -> 0 | M36: ='الاطار الموازنى راي الجهه عام'!I36 -> 0 | N36: =M36-I36 -> 0 | P36: =IF(O36>I36,O36-I36," ") | Q36: =IF(I36>O36,I36-O36," ") | R36: =IF(O36=0,,O36/I36) -> 0 | S36: =SUM(A36+B36+C36+D36+E36+F36+I36+J36+K36+L36+M36+O36) -> 0
A37: =SUM(A35:A36) -> 0 | B37: =SUM(B35:B36) -> 0 | C37: =SUM(C35:C36) -> 14000 | D37: =SUM(D35:D36) -> 1925 | E37: =SUM(E35:E36) -> 14000 | F37: ='الاطار الموازنى راي الجهه عام'!F37 -> 0 | H37: جملة نوع ( 4 ) | I37: =SUM(I35:I36) -> 7000 | J37: =SUM(J35:J36) -> 7000 | K37: =SUM(K35:K36) -> 0 | L37: =SUM(L35:L36) -> 0 | M37: ='الاطار الموازنى راي الجهه عام'!I37 -> 7000 | N37: =M37-I37 -> 0 | O37: =SUM(O35:O36) -> 7000 | P37: =IF(O37>I37,O37-I37," ") | Q37: =IF(I37>O37,I37-O37," ") | R37: =IF(O37=0,,O37/I37) -> 1 | S37: =SUM(A37+B37+C37+D37+E37+F37+I37+J37+K37+L37+M37+O37) -> 57925
A38: =A37/A847 -> 0 | B38: =B37/B847 -> 0 | C38: =C37/C847 -> 0.00074396854 | D38: =D37/D847 -> 5.9996175e-05 | E38: =E37/E847 -> 0.00045427997 | F38: ='الاطار الموازنى راي الجهه عام'!F38 -> #DIV/0! | H38: نسبة الى إيرادات النشاط | I38: =I37/I847 -> 0.00017756132 | J38: =J37/J847 -> 0.00017756132 | K38: =K37/K847 -> #DIV/0! | L38: =L37/L847 -> #DIV/0! | M38: ='الاطار الموازنى راي الجهه عام'!I38 -> 0.00017756132 | O38: =O37/O847 -> 0.00017756132 | S38: 1
A39: ='الاطار الموازنى راي الجهه عام'!A39 -> 0 | B39: ='الاطار الموازنى راي الجهه عام'!B39 -> 0 | C39: ='الاطار الموازنى راي الجهه عام'!C39 -> 0 | D39: ='الاطار الموازنى راي الجهه عام'!D39 -> 0 | E39: ='الاطار الموازنى راي الجهه عام'!E39 -> 0 | F39: ='الاطار الموازنى راي الجهه عام'!F39 -> 0 | G39: 3111020501 | H39: نوع(5) أخرى | L39: =K39*2 -> 0 | M39: ='الاطار الموازنى راي الجهه عام'!I39 -> 0 | N39: =M39-I39 -> 0 | P39: =IF(O39>I39,O39-I39," ") | Q39: =IF(I39>O39,I39-O39," ") | R39: =IF(O39=0,,O39/I39) -> 0 | S39: =SUM(A39+B39+C39+D39+E39+F39+I39+J39+K39+L39+M39+O39) -> 0
A40: =A23+A27+A32+A37+A39 -> 215000 | B40: =B23+B27+B32+B37+B39 -> 195290 | C40: =C23+C27+C32+C37+C39 -> 302000 | D40: =D23+D27+D32+D37+D39 -> 299708 | E40: =E23+E27+E32+E37+E39 -> 509000 | F40: ='الاطار الموازنى راي الجهه عام'!F40 -> 0 | H40: جملة بند (2) وقود وزيوت | I40: =I23+I27+I32+I37+I39 -> 562000 | J40: =J23+J27+J32+J37+J39 -> 562000 | K40: =K23+K27+K32+K37+K39 -> 0 | L40: =L23+L27+L32+L37+L39 -> 0 | M40: ='الاطار الموازنى راي الجهه عام'!I40 -> 584000 | N40: =M40-I40 -> 22000 | O40: =O23+O27+O32+O37+O39 -> 584000 | P40: =IF(O40>I40,O40-I40," ") -> 22000 | Q40: =IF(I40>O40,I40-O40," ") | R40: =IF(O40=0,,O40/I40) -> 1.0391459 | S40: =SUM(A40+B40+C40+D40+E40+F40+I40+J40+K40+L40+M40+O40) -> 3812998
...

Sheet موازنة 2027-2028 
A1: مشروع موازنة السنة المالية 2027/ 2028
D2: ='موازنة 2026-2027'!D2:O2 -> جهاز تنمية شبه جزيرة سيناء | P2: " القيمة بالجنيه "
A3: موازنة السنة المالية 2021/ 2022 | C3: موازنة السنة المالية 2022/ 2023 | E3: موازنة السنة المالية 2024/ 2025 | G3: الكود الاقتصادى | H3: البيان | I3: مقترح موازنة 2026/ 2027 | M3: مقترح الجهه | N3: الزيادة في راي الجهة | O3: موازنة العام المالى 2027/ 2028 | P3: التغير | R3: النسبة
A4: ربط | B4: ختامي | C4: ربط | D4: ختامي | E4: ربط | F4: ختامي | P4: الزيادة | Q4: الخفض
G5: 3110000000 | H5: التكاليف و المصروفات | S5: =S437 -> 108824000
G6: 3111000000 | H6: مجموعة (1) خامات ومواد ووقود وقطع غيار | S6: =S70 -> 5965000
G7: 3111010000 | H7: بند 1 - خامات ومدخلات انتاج | S7: =S21 -> 0
G8: 3111010100 | H8: نوع(1) خامات | S8: =S12 -> 0
G9: 3111010101 | H9: فرع (1) خامات رئيسية | I9: ='موازنة 2026-2027'!M9 -> 0 | L9: =K9*2 -> 0 | M9: ='الاطار الموازنى راي الجهه عام'!J9 -> 0 | N9: =M9-I9 -> 0 | P9: =IF(O9>I9,O9-I9," ") | Q9: =IF(I9>O9,I9-O9," ") | R9: =IF(O9=0,,O9/I9) -> 0 | S9: =SUM(A9+B9+C9+D9+E9+F9+I9+J9+K9+L9+M9+O9) -> 0
G10: 3111010102 | H10: فرع (2) خامات مساعدة | I10: ='موازنة 2026-2027'!M10 -> 0 | L10: =K10*2 -> 0 | M10: ='الاطار الموازنى راي الجهه عام'!J10 -> 0 | N10: =M10-I10 -> 0 | P10: =IF(O10>I10,O10-I10," ") | Q10: =IF(I10>O10,I10-O10," ") | R10: =IF(O10=0,,O10/I10) -> 0 | S10: =SUM(A10+B10+C10+D10+E10+F10+I10+J10+K10+L10+M10+O10) -> 0
G11: 3111010103 | H11: فرع (3) أخرى | I11: ='موازنة 2026-2027'!M11 -> 0 | L11: =K11*2 -> 0 | M11: ='الاطار الموازنى راي الجهه عام'!J11 -> 0 | N11: =M11-I11 -> 0 | P11: =IF(O11>I11,O11-I11," ") | Q11: =IF(I11>O11,I11-O11," ") | R11: =IF(O11=0,,O11/I11) -> 0 | S11: =SUM(A11+B11+C11+D11+E11+F11+I11+J11+K11+L11+M11+O11) -> 0
A12: =SUM(A9:A11) -> 0 | B12: =SUM(B9:B11) -> 0 | C12: =SUM(C9:C11) -> 0 | D12: =SUM(D9:D11) -> 0 | E12: =SUM(E9:E11) -> 0 | F12: =SUM(F9:F11) -> 0 | H12: جملة نوع ( 1 ) | I12: =SUM(I9:I11) -> 0 | J12: =SUM(J9:J11) -> 0 | K12: =SUM(K9:K11) -> 0 | L12: =SUM(L9:L11) -> 0 | M12: ='الاطار الموازنى راي الجهه عام'!J12 -> 0 | N12: =M12-I12 -> 0 | O12: =SUM(O9:O11) -> 0 | P12: =IF(O12>I12,O12-I12," ") | Q12: =IF(I12>O12,I12-O12," ") | R12: =IF(O12=0,,O12/I12) -> 0 | S12: =SUM(A12+B12+C12+D12+E12+F12+I12+J12+K12+L12+M12+O12) -> 0
A13: =A12/A847 -> #DIV/0! | B13: =B12/B847 -> #DIV/0! | C13: =C12/C847 -> #DIV/0! | D13: =D12/D847 -> #DIV/0! | E13: =E12/E847 -> #DIV/0! | F13: =F12/F847 -> #DIV/0! | H13: نسبة الى إيرادات النشاط | I13: =I12/I847 -> 0 | J13: =J12/J847 -> #DIV/0! | K13: =K12/K847 -> #DIV/0! | L13: =L12/L847 -> #DIV/0! | M13: ='الاطار الموازنى راي الجهه عام'!J13 -> 0 | O13: =O12/O847 -> 0 | S13: 1
G14: 3111010200 | H14: نوع(2) مدخلات أنتاج | M14: ='الاطار الموازنى راي الجهه عام'!J14 -> 0 | N14: =M14-I14 -> 0 | P14: =IF(O14>I14,O14-I14," ") | Q14: =IF(I14>O14,I14-O14," ") | S14: =S19 -> 0
G15: 3111010201 | H15: فرع (1) ألأراضي المستخدمة في تنفيذ مشروعات التعمير والإسكان التي يتم بيعها مع الوحدات السكنية المقامة عليها | I15: ='موازنة 2026-2027'!M15 -> 0 | L15: =K15*2 -> 0 | M15: ='الاطار الموازنى راي الجهه عام'!J15 -> 0 | N15: =M15-I15 -> 0 | P15: =IF(O15>I15,O15-I15," ") | Q15: =IF(I15>O15,I15-O15," ") | R15: =IF(O15=0,,O15/I15) -> 0 | S15: =SUM(A15+B15+C15+D15+E15+F15+I15+J15+K15+L15+M15+O15) -> 0
G16: 3111010202 | H16: فرع (2) ألأراضي المخصصة لمشروعات الاستصلاح والاستزراع التي يتم تنفيذها بغرض البيع للغير | I16: ='موازنة 2026-2027'!M16 -> 0 | L16: =K16*2 -> 0 | M16: ='الاطار الموازنى راي الجهه عام'!J16 -> 0 | N16: =M16-I16 -> 0 | P16: =IF(O16>I16,O16-I16," ") | Q16: =IF(I16>O16,I16-O16," ") | R16: =IF(O16=0,,O16/I16) -> 0 | S16: =SUM(A16+B16+C16+D16+E16+F16+I16+J16+K16+L16+M16+O16) -> 0
G17: 3111010203 | H17: فرع (3) مخلفات إنتاج يتم تشغيلها مرة أخري | I17: ='موازنة 2026-2027'!M17 -> 0 | L17: =K17*2 -> 0 | M17: ='الاطار الموازنى راي الجهه عام'!J17 -> 0 | N17: =M17-I17 -> 0 | P17: =IF(O17>I17,O17-I17," ") | Q17: =IF(I17>O17,I17-O17," ") | R17: =IF(O17=0,,O17/I17) -> 0 | S17: =SUM(A17+B17+C17+D17+E17+F17+I17+J17+K17+L17+M17+O17) -> 0
G18: 3111010204 | H18: فرع (4) مخلفات إنتاج أخري | I18: ='موازنة 2026-2027'!M18 -> 0 | L18: =K18*2 -> 0 | M18: ='الاطار الموازنى راي الجهه عام'!J18 -> 0 | N18: =M18-I18 -> 0 | P18: =IF(O18>I18,O18-I18," ") | Q18: =IF(I18>O18,I18-O18," ") | R18: =IF(O18=0,,O18/I18) -> 0 | S18: =SUM(A18+B18+C18+D18+E18+F18+I18+J18+K18+L18+M18+O18) -> 0
A19: =SUM(A15:A18) -> 0 | B19: =SUM(B15:B18) -> 0 | C19: =SUM(C15:C18) -> 0 | D19: =SUM(D15:D18) -> 0 | E19: =SUM(E15:E18) -> 0 | F19: =SUM(F15:F18) -> 0 | H19: جملة نوع ( 2 ) | I19: =SUM(I15:I18) -> 0 | J19: =SUM(J15:J18) -> 0 | K19: =SUM(K15:K18) -> 0 | L19: =SUM(L15:L18) -> 0 | M19: ='الاطار الموازنى راي الجهه عام'!J19 -> 0 | N19: =M19-I19 -> 0 | O19: =SUM(O15:O18) -> 0 | P19: =IF(O19>I19,O19-I19," ") | Q19: =IF(I19>O19,I19-O19," ") | R19: =IF(O19=0,,O19/I19) -> 0 | S19: =SUM(A19+B19+C19+D19+E19+F19+I19+J19+K19+L19+M19+O19) -> 0
A20: =A19/A847 -> #DIV/0! | B20: =B19/B847 -> #DIV/0! | C20: =C19/C847 -> #DIV/0! | D20: =D19/D847 -> #DIV/0! | E20: =E19/E847 -> #DIV/0! | F20: =F19/F847 -> #DIV/0! | H20: نسبة الى إيرادات النشاط | I20: =I19/I847 -> 0 | J20: =J19/J847 -> #DIV/0! | K20: =K19/K847 -> #DIV/0! | L20: =L19/L847 -> #DIV/0! | M20: ='الاطار الموازنى راي الجهه عام'!J20 -> 0 | O20: =O19/O847 -> 0 | S20: 1
A21: =A12+A19 -> 0 | B21: =B12+B19 -> 0 | C21: =C12+C19 -> 0 | D21: =D12+D19 -> 0 | E21: =E12+E19 -> 0 | F21: =F12+F19 -> 0 | H21: جملة بند 1 - خامات ومدخلات انتاج | I21: =I12+I19 -> 0 | J21: =J12+J19 -> 0 | K21: =K12+K19 -> 0 | L21: =K21*2 -> 0 | M21: ='الاطار الموازنى راي الجهه عام'!J21 -> 0 | N21: =M21-I21 -> 0 | O21: =O12+O19 -> 0 | P21: =IF(O21>I21,O21-I21," ") | Q21: =IF(I21>O21,I21-O21," ") | R21: =IF(O21=0,,O21/I21) -> 0 | S21: =SUM(A21+B21+C21+D21+E21+F21+I21+J21+K21+L21+M21+O21) -> 0
G22: 3111020000 | H22: بند 2 وقود وزيوت | M22: ='الاطار الموازنى راي الجهه عام'!J22 -> 0 | P22: =IF(O22>I22,O22-I22," ") | Q22: =IF(I22>O22,I22-O22," ") | S22: =S40 -> 1928000
G23: 3111020101 | H23: نوع (1) فحومات | I23: ='موازنة 2026-2027'!M23 -> 0 | L23: =K23*2 -> 0 | M23: ='الاطار الموازنى راي الجهه عام'!J23 -> 0 | N23: =M23-I23 -> 0 | P23: =IF(O23>I23,O23-I23," ") | Q23: =IF(I23>O23,I23-O23," ") | R23: =IF(O23=0,,O23/I23) -> 0 | S23: =SUM(A23+B23+C23+D23+E23+F23+I23+J23+K23+L23+M23+O23) -> 0
G24: 3111020200 | H24: نوع (2) مواد بترولية | M24: ='الاطار الموازنى راي الجهه عام'!J24 -> 0 | P24: =IF(O24>I24,O24-I24," ") | Q24: =IF(I24>O24,I24-O24," ") | S24: =S27 -> 1633000
G25: 3111020201 | H25: فرع (1) مواد بترولية للتشغيل | I25: ='موازنة 2026-2027'!M25 -> 0 | L25: =K25*2 -> 0 | M25: ='الاطار الموازنى راي الجهه عام'!J25 -> 0 | N25: =M25-I25 -> 0 | P25: =IF(O25>I25,O25-I25," ") | Q25: =IF(I25>O25,I25-O25," ") | R25: =IF(O25=0,,O25/I25) -> 0 | S25: =SUM(A25+B25+C25+D25+E25+F25+I25+J25+K25+L25+M25+O25) -> 0
G26: 3111020202 | H26: فرع (2) مواد بترولية لسيارات الركوب | I26: ='موازنة 2026-2027'!M26 -> 495000 | L26: =K26*2 -> 0 | M26: ='الاطار الموازنى راي الجهه عام'!J26 -> 569000 | N26: =M26-I26 -> 74000 | O26: 569000 | P26: =IF(O26>I26,O26-I26," ") -> 74000 | Q26: =IF(I26>O26,I26-O26," ") | R26: =IF(O26=0,,O26/I26) -> 1.1494949 | S26: =SUM(A26+B26+C26+D26+E26+F26+I26+J26+K26+L26+M26+O26) -> 1633000
A27: =SUM(A25:A26) -> 0 | B27: =SUM(B25:B26) -> 0 | C27: =SUM(C25:C26) -> 0 | D27: =SUM(D25:D26) -> 0 | E27: =SUM(E25:E26) -> 0 | F27: =SUM(F25:F26) -> 0 | H27: جملة نوع ( 2 ) | I27: =SUM(I25:I26) -> 495000 | J27: =SUM(J25:J26) -> 0 | K27: =SUM(K25:K26) -> 0 | L27: =SUM(L25:L26) -> 0 | M27: ='الاطار الموازنى راي الجهه عام'!J27 -> 569000 | N27: =M27-I27 -> 74000 | O27: =SUM(O25:O26) -> 569000 | P27: =IF(O27>I27,O27-I27," ") -> 74000 | Q27: =IF(I27>O27,I27-O27," ") | R27: =IF(O27=0,,O27/I27) -> 1.1494949 | S27: =SUM(A27+B27+C27+D27+E27+F27+I27+J27+K27+L27+M27+O27) -> 1633000
A28: =A27/A847 -> #DIV/0! | B28: =B27/B847 -> #DIV/0! | C28: =C27/C847 -> #DIV/0! | D28: =D27/D847 -> #DIV/0! | E28: =E27/E847 -> #DIV/0! | F28: =F27/F847 -> #DIV/0! | H28: نسبة الى إيرادات النشاط | I28: =I27/I847 -> 0.012556122 | J28: =J27/J847 -> #DIV/0! | K28: =K27/K847 -> #DIV/0! | L28: =L27/L847 -> #DIV/0! | M28: ='الاطار الموازنى راي الجهه عام'!J28 -> 0.012499176 | O28: =O27/O847 -> 0.012499176 | S28: 1
G29: 3111020300 | H29: نوع (3) مواد تزييت و تشحيم | M29: ='الاطار الموازنى راي الجهه عام'!J29 -> 0 | P29: =IF(O29>I29,O29-I29," ") | Q29: =IF(I29>O29,I29-O29," ") | S29: =S32 -> 272000
G30: 3111020301 | H30: فرع (1) مواد تزييت و شحومات للتشغيل | I30: ='موازنة 2026-2027'!M30 -> 0 | L30: =K30*2 -> 0 | M30: ='الاطار الموازنى راي الجهه عام'!J30 -> 0 | N30: =M30-I30 -> 0 | P30: =IF(O30>I30,O30-I30," ") | Q30: =IF(I30>O30,I30-O30," ") | R30: =IF(O30=0,,O30/I30) -> 0 | S30: =SUM(A30+B30+C30+D30+E30+F30+I30+J30+K30+L30+M30+O30) -> 0
G31: 3111020302 | H31: فرع (2) مواد تزييت وشحومات لسيارات الركوب | I31: ='موازنة 2026-2027'!M31 -> 82000 | L31: =K31*2 -> 0 | M31: ='الاطار الموازنى راي الجهه عام'!J31 -> 95000 | N31: =M31-I31 -> 13000 | O31: 95000 | P31: =IF(O31>I31,O31-I31," ") -> 13000 | Q31: =IF(I31>O31,I31-O31," ") | R31: =IF(O31=0,,O31/I31) -> 1.1585366 | S31: =SUM(A31+B31+C31+D31+E31+F31+I31+J31+K31+L31+M31+O31) -> 272000
A32: =SUM(A30:A31) -> 0 | B32: =SUM(B30:B31) -> 0 | C32: =SUM(C30:C31) -> 0 | D32: =SUM(D30:D31) -> 0 | E32: =SUM(E30:E31) -> 0 | F32: =SUM(F30:F31) -> 0 | H32: جملة نوع ( 3 ) | I32: =SUM(I30:I31) -> 82000 | J32: =SUM(J30:J31) -> 0 | K32: =SUM(K30:K31) -> 0 | L32: =SUM(L30:L31) -> 0 | M32: ='الاطار الموازنى راي الجهه عام'!J32 -> 95000 | N32: =M32-I32 -> 13000 | O32: =SUM(O30:O31) -> 95000 | P32: =IF(O32>I32,O32-I32," ") -> 13000 | Q32: =IF(I32>O32,I32-O32," ") | R32: =IF(O32=0,,O32/I32) -> 1.1585366 | S32: =SUM(A32+B32+C32+D32+E32+F32+I32+J32+K32+L32+M32+O32) -> 272000
A33: =A32/A847 -> #DIV/0! | B33: =B32/B847 -> #DIV/0! | C33: =C32/C847 -> #DIV/0! | D33: =D32/D847 -> #DIV/0! | E33: =E32/E847 -> #DIV/0! | F33: =F32/F847 -> #DIV/0! | H33: نسبة الى إيرادات النشاط | I33: =I32/I847 -> 0.0020800041 | J33: =J32/J847 -> #DIV/0! | K33: =K32/K847 -> #DIV/0! | L33: =L32/L847 -> #DIV/0! | M33: ='الاطار الموازنى راي الجهه عام'!J33 -> 0.0020868572 | O33: =O32/O847 -> 0.0020868572 | S33: 1
G34: 3111020400 | H34: نوع (4) غاز | M34: ='الاطار الموازنى راي الجهه عام'!J34 -> 0 | P34: =IF(O34>I34,O34-I34," ") | Q34: =IF(I34>O34,I34-O34," ") | S34: =S36 -> 0
G35: 3111020401 | H35: فرع (1) غاز للتشغيل | I35: ='موازنة 2026-2027'!M35 -> 7000 | L35: =K35*2 -> 0 | M35: ='الاطار الموازنى راي الجهه عام'!J35 -> 8000 | N35: =M35-I35 -> 1000 | O35: 8000 | P35: =IF(O35>I35,O35-I35," ") -> 1000 | Q35: =IF(I35>O35,I35-O35," ") | R35: =IF(O35=0,,O35/I35) -> 1.1428571 | S35: =SUM(A35+B35+C35+D35+E35+F35+I35+J35+K35+L35+M35+O35) -> 23000
G36: 3111020402 | H36: فرع (2) غاز لسيارات الركوب | I36: ='موازنة 2026-2027'!M36 -> 0 | L36: =K36*2 -> 0 | M36: ='الاطار الموازنى راي الجهه عام'!J36 -> 0 | N36: =M36-I36 -> 0 | P36: =IF(O36>I36,O36-I36," ") | Q36: =IF(I36>O36,I36-O36," ") | R36: =IF(O36=0,,O36/I36) -> 0 | S36: =SUM(A36+B36+C36+D36+E36+F36+I36+J36+K36+L36+M36+O36) -> 0
A37: =SUM(A35:A36) -> 0 | B37: =SUM(B35:B36) -> 0 | C37: =SUM(C35:C36) -> 0 | D37: =SUM(D35:D36) -> 0 | E37: =SUM(E35:E36) -> 0 | F37: =SUM(F35:F36) -> 0 | H37: جملة نوع ( 4 ) | I37: =SUM(I35:I36) -> 7000 | J37: =SUM(J35:J36) -> 0 | K37: =SUM(K35:K36) -> 0 | L37: =SUM(L35:L36) -> 0 | M37: ='الاطار الموازنى راي الجهه عام'!J37 -> 8000 | N37: =M37-I37 -> 1000 | O37: =SUM(O35:O36) -> 8000 | P37: =IF(O37>I37,O37-I37," ") -> 1000 | Q37: =IF(I37>O37,I37-O37," ") | R37: =IF(O37=0,,O37/I37) -> 1.1428571 | S37: =SUM(A37+B37+C37+D37+E37+F37+I37+J37+K37+L37+M37+O37) -> 23000
A38: =A37/A847 -> #DIV/0! | B38: =B37/B847 -> #DIV/0! | C38: =C37/C847 -> #DIV/0! | D38: =D37/D847 -> #DIV/0! | E38: =E37/E847 -> #DIV/0! | F38: =F37/F847 -> #DIV/0! | H38: نسبة الى إيرادات النشاط | I38: =I37/I847 -> 0.00017756132 | J38: =J37/J847 -> #DIV/0! | K38: =K37/K847 -> #DIV/0! | L38: =L37/L847 -> #DIV/0! | M38: ='الاطار الموازنى راي الجهه عام'!J38 -> 0.00017573534 | O38: =O37/O847 -> 0.00017573534 | S38: 1
G39: 3111020501 | H39: نوع(5) أخرى | I39: ='موازنة 2026-2027'!M39 -> 0 | L39: =K39*2 -> 0 | M39: ='الاطار الموازنى راي الجهه عام'!J39 -> 0 | N39: =M39-I39 -> 0 | P39: =IF(O39>I39,O39-I39," ") | Q39: =IF(I39>O39,I39-O39," ") | R39: =IF(O39=0,,O39/I39) -> 0 | S39: =SUM(A39+B39+C39+D39+E39+F39+I39+J39+K39+L39+M39+O39) -> 0
A40: =A23+A27+A32+A37+A39 -> 0 | B40: =B23+B27+B32+B37+B39 -> 0 | C40: =C23+C27+C32+C37+C39 -> 0 | D40: =D23+D27+D32+D37+D39 -> 0 | E40: =E23+E27+E32+E37+E39 -> 0 | F40: =F23+F27+F32+F37+F39 -> 0 | H40: جملة بند (2) وقود وزيوت | I40: =I23+I27+I32+I37+I39 -> 584000 | J40: =J23+J27+J32+J37+J39 -> 0 | K40: =K23+K27+K32+K37+K39 -> 0 | L40: =L23+L27+L32+L37+L39 -> 0 | M40: ='الاطار الموازنى راي الجهه عام'!J40 -> 672000 | N40: =M40-I40 -> 88000 | O40: =O23+O27+O32+O37+O39 -> 672000 | P40: =IF(O40>I40,O40-I40," ") -> 88000 | Q40: =IF(I40>O40,I40-O40," ") | R40: =IF(O40=0,,O40/I40) -> 1.1506849 | S40: =SUM(A40+B40+C40+D40+E40+F40+I40+J40+K40+L40+M40+O40) -> 1928000
...

Sheet موازنة 2028 -2029
A1: مشروع موازنة السنة المالية 2028/ 2029
D2: ='موازنة 2027-2028 '!D2:O2 -> جهاز تنمية شبه جزيرة سيناء | P2: " القيمة بالجنيه "
A3: موازنة السنة المالية 2021/ 2022 | C3: موازنة السنة المالية 2022/ 2023 | E3: موازنة السنة المالية 2024/ 2025 | G3: الكود الاقتصادى | H3: البيان | I3: مقترح موازنة 2027/ 2028 | M3: مقترح الجهه | N3: الزيادة في راي الجهة | O3: موازنة العام المالى 2028/ 2029 | P3: التغير | R3: النسبة
A4: ربط | B4: ختامي | C4: ربط | D4: ختامي | E4: ربط | F4: ختامي | P4: الزيادة | Q4: الخفض
G5: 3110000000 | H5: التكاليف و المصروفات | S5: =S437 -> 117573000
G6: 3111000000 | H6: مجموعة (1) خامات ومواد ووقود وقطع غيار | S6: =S70 -> 7072000
G7: 3111010000 | H7: بند 1 - خامات ومدخلات انتاج | S7: =S21 -> 0
G8: 3111010100 | H8: نوع(1) خامات | S8: =S12 -> 0
G9: 3111010101 | H9: فرع (1) خامات رئيسية | I9: ='موازنة 2027-2028 '!M9 -> 0 | L9: =K9*2 -> 0 | M9: ='الاطار الموازنى راي الجهه عام'!K9 -> 0 | N9: =M9-I9 -> 0 | P9: =IF(O9>I9,O9-I9," ") | Q9: =IF(I9>O9,I9-O9," ") | R9: =IF(O9=0,,O9/I9) -> 0 | S9: =SUM(A9+B9+C9+D9+E9+F9+I9+J9+K9+L9+M9+O9) -> 0
G10: 3111010102 | H10: فرع (2) خامات مساعدة | I10: ='موازنة 2027-2028 '!M10 -> 0 | L10: =K10*2 -> 0 | M10: ='الاطار الموازنى راي الجهه عام'!K10 -> 0 | N10: =M10-I10 -> 0 | P10: =IF(O10>I10,O10-I10," ") | Q10: =IF(I10>O10,I10-O10," ") | R10: =IF(O10=0,,O10/I10) -> 0 | S10: =SUM(A10+B10+C10+D10+E10+F10+I10+J10+K10+L10+M10+O10) -> 0
G11: 3111010103 | H11: فرع (3) أخرى | I11: ='موازنة 2027-2028 '!M11 -> 0 | L11: =K11*2 -> 0 | M11: ='الاطار الموازنى راي الجهه عام'!K11 -> 0 | N11: =M11-I11 -> 0 | P11: =IF(O11>I11,O11-I11," ") | Q11: =IF(I11>O11,I11-O11," ") | R11: =IF(O11=0,,O11/I11) -> 0 | S11: =SUM(A11+B11+C11+D11+E11+F11+I11+J11+K11+L11+M11+O11) -> 0
A12: =SUM(A9:A11) -> 0 | B12: =SUM(B9:B11) -> 0 | C12: =SUM(C9:C11) -> 0 | D12: =SUM(D9:D11) -> 0 | E12: =SUM(E9:E11) -> 0 | F12: =SUM(F9:F11) -> 0 | H12: جملة نوع ( 1 ) | I12: =SUM(I9:I11) -> 0 | J12: =SUM(J9:J11) -> 0 | K12: =SUM(K9:K11) -> 0 | L12: =SUM(L9:L11) -> 0 | M12: ='الاطار الموازنى راي الجهه عام'!K12 -> 0 | N12: =M12-I12 -> 0 | O12: =SUM(O9:O11) -> 0 | P12: =IF(O12>I12,O12-I12," ") | Q12: =IF(I12>O12,I12-O12," ") | R12: =IF(O12=0,,O12/I12) -> 0 | S12: =SUM(A12+B12+C12+D12+E12+F12+I12+J12+K12+L12+M12+O12) -> 0
A13: =A12/A847 -> #DIV/0! | B13: =B12/B847 -> #DIV/0! | C13: =C12/C847 -> #DIV/0! | D13: =D12/D847 -> #DIV/0! | E13: =E12/E847 -> #DIV/0! | F13: =F12/F847 -> #DIV/0! | H13: نسبة الى إيرادات النشاط | I13: =I12/I847 -> 0 | J13: =J12/J847 -> #DIV/0! | K13: =K12/K847 -> #DIV/0! | L13: =L12/L847 -> #DIV/0! | M13: ='الاطار الموازنى راي الجهه عام'!K13 -> 0 | O13: =O12/O847 -> 0 | S13: 1
G14: 3111010200 | H14: نوع(2) مدخلات أنتاج | M14: ='الاطار الموازنى راي الجهه عام'!K14 -> 0 | N14: =M14-I14 -> 0 | P14: =IF(O14>I14,O14-I14," ") | Q14: =IF(I14>O14,I14-O14," ") | S14: =S19 -> 0
G15: 3111010201 | H15: فرع (1) ألأراضي المستخدمة في تنفيذ مشروعات التعمير والإسكان التي يتم بيعها مع الوحدات السكنية المقامة عليها | I15: ='موازنة 2027-2028 '!M15 -> 0 | L15: =K15*2 -> 0 | M15: ='الاطار الموازنى راي الجهه عام'!K15 -> 0 | N15: =M15-I15 -> 0 | P15: =IF(O15>I15,O15-I15," ") | Q15: =IF(I15>O15,I15-O15," ") | R15: =IF(O15=0,,O15/I15) -> 0 | S15: =SUM(A15+B15+C15+D15+E15+F15+I15+J15+K15+L15+M15+O15) -> 0
G16: 3111010202 | H16: فرع (2) ألأراضي المخصصة لمشروعات الاستصلاح والاستزراع التي يتم تنفيذها بغرض البيع للغير | I16: ='موازنة 2027-2028 '!M16 -> 0 | L16: =K16*2 -> 0 | M16: ='الاطار الموازنى راي الجهه عام'!K16 -> 0 | N16: =M16-I16 -> 0 | P16: =IF(O16>I16,O16-I16," ") | Q16: =IF(I16>O16,I16-O16," ") | R16: =IF(O16=0,,O16/I16) -> 0 | S16: =SUM(A16+B16+C16+D16+E16+F16+I16+J16+K16+L16+M16+O16) -> 0
G17: 3111010203 | H17: فرع (3) مخلفات إنتاج يتم تشغيلها مرة أخري | I17: ='موازنة 2027-2028 '!M17 -> 0 | L17: =K17*2 -> 0 | M17: ='الاطار الموازنى راي الجهه عام'!K17 -> 0 | N17: =M17-I17 -> 0 | P17: =IF(O17>I17,O17-I17," ") | Q17: =IF(I17>O17,I17-O17," ") | R17: =IF(O17=0,,O17/I17) -> 0 | S17: =SUM(A17+B17+C17+D17+E17+F17+I17+J17+K17+L17+M17+O17) -> 0
G18: 3111010204 | H18: فرع (4) مخلفات إنتاج أخري | I18: ='موازنة 2027-2028 '!M18 -> 0 | L18: =K18*2 -> 0 | M18: ='الاطار الموازنى راي الجهه عام'!K18 -> 0 | N18: =M18-I18 -> 0 | P18: =IF(O18>I18,O18-I18," ") | Q18: =IF(I18>O18,I18-O18," ") | R18: =IF(O18=0,,O18/I18) -> 0 | S18: =SUM(A18+B18+C18+D18+E18+F18+I18+J18+K18+L18+M18+O18) -> 0
A19: =SUM(A15:A18) -> 0 | B19: =SUM(B15:B18) -> 0 | C19: =SUM(C15:C18) -> 0 | D19: =SUM(D15:D18) -> 0 | E19: =SUM(E15:E18) -> 0 | F19: =SUM(F15:F18) -> 0 | H19: جملة نوع ( 2 ) | I19: =SUM(I15:I18) -> 0 | J19: =SUM(J15:J18) -> 0 | K19: =SUM(K15:K18) -> 0 | L19: =SUM(L15:L18) -> 0 | M19: ='الاطار الموازنى راي الجهه عام'!K19 -> 0 | N19: =M19-I19 -> 0 | O19: =SUM(O15:O18) -> 0 | P19: =IF(O19>I19,O19-I19," ") | Q19: =IF(I19>O19,I19-O19," ") | R19: =IF(O19=0,,O19/I19) -> 0 | S19: =SUM(A19+B19+C19+D19+E19+F19+I19+J19+K19+L19+M19+O19) -> 0
A20: =A19/A847 -> #DIV/0! | B20: =B19/B847 -> #DIV/0! | C20: =C19/C847 -> #DIV/0! | D20: =D19/D847 -> #DIV/0! | E20: =E19/E847 -> #DIV/0! | F20: =F19/F847 -> #DIV/0! | H20: نسبة الى إيرادات النشاط | I20: =I19/I847 -> 0 | J20: =J19/J847 -> #DIV/0! | K20: =K19/K847 -> #DIV/0! | L20: =L19/L847 -> #DIV/0! | M20: ='الاطار الموازنى راي الجهه عام'!K20 -> 0 | O20: =O19/O847 -> 0 | S20: 1
A21: =A12+A19 -> 0 | B21: =B12+B19 -> 0 | C21: =C12+C19 -> 0 | D21: =D12+D19 -> 0 | E21: =E12+E19 -> 0 | F21: =F12+F19 -> 0 | H21: جملة بند 1 - خامات ومدخلات انتاج | I21: =I12+I19 -> 0 | J21: =J12+J19 -> 0 | K21: =K12+K19 -> 0 | L21: =K21*2 -> 0 | M21: ='الاطار الموازنى راي الجهه عام'!K21 -> 0 | N21: =M21-I21 -> 0 | O21: =O12+O19 -> 0 | P21: =IF(O21>I21,O21-I21," ") | Q21: =IF(I21>O21,I21-O21," ") | R21: =IF(O21=0,,O21/I21) -> 0 | S21: =SUM(A21+B21+C21+D21+E21+F21+I21+J21+K21+L21+M21+O21) -> 0
G22: 3111020000 | H22: بند 2 وقود وزيوت | M22: ='الاطار الموازنى راي الجهه عام'!K22 -> 0 | P22: =IF(O22>I22,O22-I22," ") | Q22: =IF(I22>O22,I22-O22," ") | S22: =S40 -> 2284000
G23: 3111020101 | H23: نوع (1) فحومات | I23: ='موازنة 2027-2028 '!M23 -> 0 | L23: =K23*2 -> 0 | M23: ='الاطار الموازنى راي الجهه عام'!K23 -> 0 | N23: =M23-I23 -> 0 | P23: =IF(O23>I23,O23-I23," ") | Q23: =IF(I23>O23,I23-O23," ") | R23: =IF(O23=0,,O23/I23) -> 0 | S23: =SUM(A23+B23+C23+D23+E23+F23+I23+J23+K23+L23+M23+O23) -> 0
G24: 3111020200 | H24: نوع (2) مواد بترولية | I24: ='موازنة 2027-2028 '!M24 -> 0 | M24: ='الاطار الموازنى راي الجهه عام'!K24 -> 0 | P24: =IF(O24>I24,O24-I24," ") | Q24: =IF(I24>O24,I24-O24," ") | S24: =S27 -> 1935000
G25: 3111020201 | H25: فرع (1) مواد بترولية للتشغيل | I25: ='موازنة 2027-2028 '!M25 -> 0 | L25: =K25*2 -> 0 | M25: ='الاطار الموازنى راي الجهه عام'!K25 -> 0 | N25: =M25-I25 -> 0 | P25: =IF(O25>I25,O25-I25," ") | Q25: =IF(I25>O25,I25-O25," ") | R25: =IF(O25=0,,O25/I25) -> 0 | S25: =SUM(A25+B25+C25+D25+E25+F25+I25+J25+K25+L25+M25+O25) -> 0
G26: 3111020202 | H26: فرع (2) مواد بترولية لسيارات الركوب | I26: ='موازنة 2027-2028 '!M26 -> 569000 | L26: =K26*2 -> 0 | M26: ='الاطار الموازنى راي الجهه عام'!K26 -> 683000 | N26: =M26-I26 -> 114000 | O26: 683000 | P26: =IF(O26>I26,O26-I26," ") -> 114000 | Q26: =IF(I26>O26,I26-O26," ") | R26: =IF(O26=0,,O26/I26) -> 1.2003515 | S26: =SUM(A26+B26+C26+D26+E26+F26+I26+J26+K26+L26+M26+O26) -> 1935000
A27: =SUM(A25:A26) -> 0 | B27: =SUM(B25:B26) -> 0 | C27: =SUM(C25:C26) -> 0 | D27: =SUM(D25:D26) -> 0 | E27: =SUM(E25:E26) -> 0 | F27: =SUM(F25:F26) -> 0 | H27: جملة نوع ( 2 ) | I27: ='موازنة 2027-2028 '!M27 -> 569000 | J27: =SUM(J25:J26) -> 0 | K27: =SUM(K25:K26) -> 0 | L27: =SUM(L25:L26) -> 0 | M27: ='الاطار الموازنى راي الجهه عام'!K27 -> 683000 | N27: =M27-I27 -> 114000 | O27: =SUM(O25:O26) -> 683000 | P27: =IF(O27>I27,O27-I27," ") -> 114000 | Q27: =IF(I27>O27,I27-O27," ") | R27: =IF(O27=0,,O27/I27) -> 1.2003515 | S27: =SUM(A27+B27+C27+D27+E27+F27+I27+J27+K27+L27+M27+O27) -> 1935000
A28: =A27/A847 -> #DIV/0! | B28: =B27/B847 -> #DIV/0! | C28: =C27/C847 -> #DIV/0! | D28: =D27/D847 -> #DIV/0! | E28: =E27/E847 -> #DIV/0! | F28: =F27/F847 -> #DIV/0! | H28: نسبة الى إيرادات النشاط | I28: ='موازنة 2027-2028 '!M28 -> 0.012499176 | J28: =J27/J847 -> #DIV/0! | K28: =K27/K847 -> #DIV/0! | L28: =L27/L847 -> #DIV/0! | M28: ='الاطار الموازنى راي الجهه عام'!K28 -> 0.01250389 | O28: =O27/O847 -> 0.01250389 | S28: 1
G29: 3111020300 | H29: نوع (3) مواد تزييت و تشحيم | I29: ='موازنة 2027-2028 '!M29 -> 0 | M29: ='الاطار الموازنى راي الجهه عام'!K29 -> 0 | P29: =IF(O29>I29,O29-I29," ") | Q29: =IF(I29>O29,I29-O29," ") | S29: =S32 -> 323000
G30: 3111020301 | H30: فرع (1) مواد تزييت و شحومات للتشغيل | I30: ='موازنة 2027-2028 '!M30 -> 0 | L30: =K30*2 -> 0 | M30: ='الاطار الموازنى راي الجهه عام'!K30 -> 0 | N30: =M30-I30 -> 0 | P30: =IF(O30>I30,O30-I30," ") | Q30: =IF(I30>O30,I30-O30," ") | R30: =IF(O30=0,,O30/I30) -> 0 | S30: =SUM(A30+B30+C30+D30+E30+F30+I30+J30+K30+L30+M30+O30) -> 0
G31: 3111020302 | H31: فرع (2) مواد تزييت وشحومات لسيارات الركوب | I31: ='موازنة 2027-2028 '!M31 -> 95000 | L31: =K31*2 -> 0 | M31: ='الاطار الموازنى راي الجهه عام'!K31 -> 114000 | N31: =M31-I31 -> 19000 | O31: 114000 | P31: =IF(O31>I31,O31-I31," ") -> 19000 | Q31: =IF(I31>O31,I31-O31," ") | R31: =IF(O31=0,,O31/I31) -> 1.2 | S31: =SUM(A31+B31+C31+D31+E31+F31+I31+J31+K31+L31+M31+O31) -> 323000
A32: =SUM(A30:A31) -> 0 | B32: =SUM(B30:B31) -> 0 | C32: =SUM(C30:C31) -> 0 | D32: =SUM(D30:D31) -> 0 | E32: =SUM(E30:E31) -> 0 | F32: =SUM(F30:F31) -> 0 | H32: جملة نوع ( 3 ) | I32: ='موازنة 2027-2028 '!M32 -> 95000 | J32: =SUM(J30:J31) -> 0 | K32: =SUM(K30:K31) -> 0 | L32: =SUM(L30:L31) -> 0 | M32: ='الاطار الموازنى راي الجهه عام'!K32 -> 114000 | N32: =M32-I32 -> 19000 | O32: =SUM(O30:O31) -> 114000 | P32: =IF(O32>I32,O32-I32," ") -> 19000 | Q32: =IF(I32>O32,I32-O32," ") | R32: =IF(O32=0,,O32/I32) -> 1.2 | S32: =SUM(A32+B32+C32+D32+E32+F32+I32+J32+K32+L32+M32+O32) -> 323000
A33: =A32/A847 -> #DIV/0! | B33: =B32/B847 -> #DIV/0! | C33: =C32/C847 -> #DIV/0! | D33: =D32/D847 -> #DIV/0! | E33: =E32/E847 -> #DIV/0! | F33: =F32/F847 -> #DIV/0! | H33: نسبة الى إيرادات النشاط | I33: ='موازنة 2027-2028 '!M33 -> 0.0020868572 | J33: =J32/J847 -> #DIV/0! | K33: =K32/K847 -> #DIV/0! | L33: =L32/L847 -> #DIV/0! | M33: ='الاطار الموازنى راي الجهه عام'!K33 -> 0.0020870329 | O33: =O32/O847 -> 0.0020870329 | S33: 1
G34: 3111020400 | H34: نوع (4) غاز | I34: ='موازنة 2027-2028 '!M34 -> 0 | M34: ='الاطار الموازنى راي الجهه عام'!K34 -> 0 | P34: =IF(O34>I34,O34-I34," ") | Q34: =IF(I34>O34,I34-O34," ") | S34: =S36 -> 0
G35: 3111020401 | H35: فرع (1) غاز للتشغيل | I35: ='موازنة 2027-2028 '!M35 -> 8000 | L35: =K35*2 -> 0 | M35: ='الاطار الموازنى راي الجهه عام'!K35 -> 9000 | N35: =M35-I35 -> 1000 | O35: 9000 | P35: =IF(O35>I35,O35-I35," ") -> 1000 | Q35: =IF(I35>O35,I35-O35," ") | R35: =IF(O35=0,,O35/I35) -> 1.125 | S35: =SUM(A35+B35+C35+D35+E35+F35+I35+J35+K35+L35+M35+O35) -> 26000
G36: 3111020402 | H36: فرع (2) غاز لسيارات الركوب | I36: ='موازنة 2027-2028 '!M36 -> 0 | L36: =K36*2 -> 0 | M36: ='الاطار الموازنى راي الجهه عام'!K36 -> 0 | N36: =M36-I36 -> 0 | O36: 0 | P36: =IF(O36>I36,O36-I36," ") | Q36: =IF(I36>O36,I36-O36," ") | R36: =IF(O36=0,,O36/I36) -> 0 | S36: =SUM(A36+B36+C36+D36+E36+F36+I36+J36+K36+L36+M36+O36) -> 0
A37: =SUM(A35:A36) -> 0 | B37: =SUM(B35:B36) -> 0 | C37: =SUM(C35:C36) -> 0 | D37: =SUM(D35:D36) -> 0 | E37: =SUM(E35:E36) -> 0 | F37: =SUM(F35:F36) -> 0 | H37: جملة نوع ( 4 ) | I37: ='موازنة 2027-2028 '!M37 -> 8000 | J37: =SUM(J35:J36) -> 0 | K37: =SUM(K35:K36) -> 0 | L37: =SUM(L35:L36) -> 0 | M37: ='الاطار الموازنى راي الجهه عام'!K37 -> 9000 | N37: =M37-I37 -> 1000 | O37: =SUM(O35:O36) -> 9000 | P37: =IF(O37>I37,O37-I37," ") -> 1000 | Q37: =IF(I37>O37,I37-O37," ") | R37: =IF(O37=0,,O37/I37) -> 1.125 | S37: =SUM(A37+B37+C37+D37+E37+F37+I37+J37+K37+L37+M37+O37) -> 26000
A38: =A37/A847 -> #DIV/0! | B38: =B37/B847 -> #DIV/0! | C38: =C37/C847 -> #DIV/0! | D38: =D37/D847 -> #DIV/0! | E38: =E37/E847 -> #DIV/0! | F38: =F37/F847 -> #DIV/0! | H38: نسبة الى إيرادات النشاط | I38: ='موازنة 2027-2028 '!M38 -> 0.00017573534 | J38: =J37/J847 -> #DIV/0! | K38: =K37/K847 -> #DIV/0! | L38: =L37/L847 -> #DIV/0! | M38: ='الاطار الموازنى راي الجهه عام'!K38 -> 0.00016476576 | O38: =O37/O847 -> 0.00016476576 | S38: 1
G39: 3111020501 | H39: نوع(5) أخرى | I39: ='موازنة 2027-2028 '!M39 -> 0 | L39: =K39*2 -> 0 | M39: ='الاطار الموازنى راي الجهه عام'!K39 -> 0 | N39: =M39-I39 -> 0 | P39: =IF(O39>I39,O39-I39," ") | Q39: =IF(I39>O39,I39-O39," ") | R39: =IF(O39=0,,O39/I39) -> 0 | S39: =SUM(A39+B39+C39+D39+E39+F39+I39+J39+K39+L39+M39+O39) -> 0
A40: =A23+A27+A32+A37+A39 -> 0 | B40: =B23+B27+B32+B37+B39 -> 0 | C40: =C23+C27+C32+C37+C39 -> 0 | D40: =D23+D27+D32+D37+D39 -> 0 | E40: =E23+E27+E32+E37+E39 -> 0 | F40: =F23+F27+F32+F37+F39 -> 0 | H40: جملة بند (2) وقود وزيوت | I40: ='موازنة 2027-2028 '!M40 -> 672000 | J40: =J23+J27+J32+J37+J39 -> 0 | K40: =K23+K27+K32+K37+K39 -> 0 | L40: =L23+L27+L32+L37+L39 -> 0 | M40: ='الاطار الموازنى راي الجهه عام'!K40 -> 806000 | N40: =M40-I40 -> 134000 | O40: =O23+O27+O32+O37+O39 -> 806000 | P40: =IF(O40>I40,O40-I40," ") -> 134000 | Q40: =IF(I40>O40,I40-O40," ") | R40: =IF(O40=0,,O40/I40) -> 1.1994048 | S40: =SUM(A40+B40+C40+D40+E40+F40+I40+J40+K40+L40+M40+O40) -> 2284000
...

Sheet موازنة 2029-2030
A1: مشروع موازنة السنة المالية 2029/ 2030
D2: ='موازنة 2028 -2029'!D2:O2 -> جهاز تنمية شبه جزيرة سيناء | P2: " القيمة بالجنيه "
A3: موازنة السنة المالية 2021/ 2022 | C3: موازنة السنة المالية 2022/ 2023 | E3: موازنة السنة المالية 2024/ 2025 | G3: الكود الاقتصادى | H3: البيان | I3: مقترح موازنة 2028/ 2029 | M3: مقترح الجهه | N3: الزيادة في راي الجهة | O3: موازنة العام المالى 2029/ 2030 | P3: التغير | R3: النسبة
A4: ربط | B4: ختامي | C4: ربط | D4: ختامي | E4: ربط | F4: ختامي | J4: ربط معدل ديسمبر2024 | K4: فعلى ديسمبر2024 | L4: المتوقع | P4: الزيادة | Q4: الخفض
G5: 3110000000 | H5: التكاليف و المصروفات | S5: =S437 -> 40256000
G6: 3111000000 | H6: مجموعة (1) خامات ومواد ووقود وقطع غيار | S6: =S70 -> 2495000
G7: 3111010000 | H7: بند 1 - خامات ومدخلات انتاج | S7: =S21 -> 0
G8: 3111010100 | H8: نوع(1) خامات | S8: =S12 -> 0
G9: 3111010101 | H9: فرع (1) خامات رئيسية | I9: ='موازنة 2028 -2029'!M9 -> 0 | L9: =K9*2 -> 0 | M9: ='الاطار الموازنى راي الجهه عام'!M9 -> 0 | N9: =M9-I9 -> 0 | P9: =IF(O9>I9,O9-I9," ") | Q9: =IF(I9>O9,I9-O9," ") | R9: =IF(O9=0,,O9/I9) -> 0 | S9: =SUM(A9+B9+C9+D9+E9+F9+I9+J9+K9+L9+M9+O9) -> 0
G10: 3111010102 | H10: فرع (2) خامات مساعدة | I10: ='موازنة 2028 -2029'!M10 -> 0 | L10: =K10*2 -> 0 | M10: ='الاطار الموازنى راي الجهه عام'!M10 -> 0 | N10: =M10-I10 -> 0 | P10: =IF(O10>I10,O10-I10," ") | Q10: =IF(I10>O10,I10-O10," ") | R10: =IF(O10=0,,O10/I10) -> 0 | S10: =SUM(A10+B10+C10+D10+E10+F10+I10+J10+K10+L10+M10+O10) -> 0
G11: 3111010103 | H11: فرع (3) أخرى | I11: ='موازنة 2028 -2029'!M11 -> 0 | L11: =K11*2 -> 0 | M11: ='الاطار الموازنى راي الجهه عام'!M11 -> 0 | N11: =M11-I11 -> 0 | P11: =IF(O11>I11,O11-I11," ") | Q11: =IF(I11>O11,I11-O11," ") | R11: =IF(O11=0,,O11/I11) -> 0 | S11: =SUM(A11+B11+C11+D11+E11+F11+I11+J11+K11+L11+M11+O11) -> 0
A12: =SUM(A9:A11) -> 0 | B12: =SUM(B9:B11) -> 0 | C12: =SUM(C9:C11) -> 0 | D12: =SUM(D9:D11) -> 0 | E12: =SUM(E9:E11) -> 0 | F12: =SUM(F9:F11) -> 0 | H12: جملة نوع ( 1 ) | I12: ='موازنة 2028 -2029'!M12 -> 0 | J12: =SUM(J9:J11) -> 0 | K12: =SUM(K9:K11) -> 0 | L12: =SUM(L9:L11) -> 0 | M12: ='الاطار الموازنى راي الجهه عام'!M12 -> 0 | N12: =M12-I12 -> 0 | O12: =SUM(O9:O11) -> 0 | P12: =IF(O12>I12,O12-I12," ") | Q12: =IF(I12>O12,I12-O12," ") | R12: =IF(O12=0,,O12/I12) -> 0 | S12: =SUM(A12+B12+C12+D12+E12+F12+I12+J12+K12+L12+M12+O12) -> 0
A13: =A12/A847 -> #DIV/0! | B13: =B12/B847 -> #DIV/0! | C13: =C12/C847 -> #DIV/0! | D13: =D12/D847 -> #DIV/0! | E13: =E12/E847 -> #DIV/0! | F13: =F12/F847 -> #DIV/0! | H13: نسبة الى إيرادات النشاط | I13: ='موازنة 2028 -2029'!M13 -> 0 | J13: =J12/J847 -> #DIV/0! | K13: =K12/K847 -> #DIV/0! | L13: =L12/L847 -> #DIV/0! | M13: ='الاطار الموازنى راي الجهه عام'!M13 -> #DIV/0! | O13: =O12/O847 -> #DIV/0! | S13: 1
G14: 3111010200 | H14: نوع(2) مدخلات أنتاج | I14: ='موازنة 2028 -2029'!M14 -> 0 | M14: ='الاطار الموازنى راي الجهه عام'!M14 -> 0 | N14: =M14-I14 -> 0 | P14: =IF(O14>I14,O14-I14," ") | Q14: =IF(I14>O14,I14-O14," ") | S14: =S19 -> 0
G15: 3111010201 | H15: فرع (1) ألأراضي المستخدمة في تنفيذ مشروعات التعمير والإسكان التي يتم بيعها مع الوحدات السكنية المقامة عليها | I15: ='موازنة 2028 -2029'!M15 -> 0 | L15: =K15*2 -> 0 | M15: ='الاطار الموازنى راي الجهه عام'!M15 -> 0 | N15: =M15-I15 -> 0 | P15: =IF(O15>I15,O15-I15," ") | Q15: =IF(I15>O15,I15-O15," ") | R15: =IF(O15=0,,O15/I15) -> 0 | S15: =SUM(A15+B15+C15+D15+E15+F15+I15+J15+K15+L15+M15+O15) -> 0
G16: 3111010202 | H16: فرع (2) ألأراضي المخصصة لمشروعات الاستصلاح والاستزراع التي يتم تنفيذها بغرض البيع للغير | I16: ='موازنة 2028 -2029'!M16 -> 0 | L16: =K16*2 -> 0 | M16: ='الاطار الموازنى راي الجهه عام'!M16 -> 0 | N16: =M16-I16 -> 0 | P16: =IF(O16>I16,O16-I16," ") | Q16: =IF(I16>O16,I16-O16," ") | R16: =IF(O16=0,,O16/I16) -> 0 | S16: =SUM(A16+B16+C16+D16+E16+F16+I16+J16+K16+L16+M16+O16) -> 0
G17: 3111010203 | H17: فرع (3) مخلفات إنتاج يتم تشغيلها مرة أخري | I17: ='موازنة 2028 -2029'!M17 -> 0 | L17: =K17*2 -> 0 | M17: ='الاطار الموازنى راي الجهه عام'!M17 -> 0 | N17: =M17-I17 -> 0 | P17: =IF(O17>I17,O17-I17," ") | Q17: =IF(I17>O17,I17-O17," ") | R17: =IF(O17=0,,O17/I17) -> 0 | S17: =SUM(A17+B17+C17+D17+E17+F17+I17+J17+K17+L17+M17+O17) -> 0
G18: 3111010204 | H18: فرع (4) مخلفات إنتاج أخري | I18: ='موازنة 2028 -2029'!M18 -> 0 | L18: =K18*2 -> 0 | M18: ='الاطار الموازنى راي الجهه عام'!M18 -> 0 | N18: =M18-I18 -> 0 | P18: =IF(O18>I18,O18-I18," ") | Q18: =IF(I18>O18,I18-O18," ") | R18: =IF(O18=0,,O18/I18) -> 0 | S18: =SUM(A18+B18+C18+D18+E18+F18+I18+J18+K18+L18+M18+O18) -> 0
